Workbook

Sheet M1
A1: ALKAMO — M1
A2: N° | B2: THÈME | C2: MOTS
A3: 1 | B3: VÊTEMENT | C3: =COUNTA(M1_mots!A3:A5000) -> 858
A4: 2 | B4: CHASSE ET PECHE | C4: =COUNTA(M1_mots!B3:B5000) -> 905
A5: 3 | B5: LANGUE | C5: =COUNTA(M1_mots!C3:C5000) -> 559
A6: 4 | B6: MAMMIFÈRE | C6: =COUNTA(M1_mots!D3:D5000) -> 600
A7: 5 | B7: TRANSPORT | C7: =COUNTA(M1_mots!E3:E5000) -> 803
A8: 6 | B8: ÉCONOMIE | C8: =COUNTA(M1_mots!F3:F5000) -> 666
A9: 7 | B9: SPORT | C9: =COUNTA(M1_mots!G3:G5000) -> 678
A10: 8 | B10: RELIGION | C10: =COUNTA(M1_mots!H3:H5000) -> 691
A11: 9 | B11: ÉCOLE | C11: =COUNTA(M1_mots!I3:I5000) -> 468
A12: 10 | B12: OUTIL ET MÉTIER | C12: =COUNTA(M1_mots!J3:J5000) -> 837
A13: 11 | B13: POLITIQUE | C13: =COUNTA(M1_mots!K3:K5000) -> 562
A14: 12 | B14: MUSIQUE | C14: =COUNTA(M1_mots!L3:L5000) -> 722
A15: 13 | B15: MINÉRAL | C15: =COUNTA(M1_mots!M3:M5000) -> 723
A16: 14 | B16: MESURE ET INSTRUMENT | C16: =COUNTA(M1_mots!N3:N5000) -> 810
A17: 15 | B17: ARTISANAT | C17: =COUNTA(M1_mots!O3:O5000) -> 679
A18: 16 | B18: FRUIT | C18: =COUNTA(M1_mots!P3:P5000) -> 603
A19: 17 | B19: ARBRE | C19: =COUNTA(M1_mots!Q3:Q5000) -> 502
A20: 18 | B20: MÉDECINE | C20: =COUNTA(M1_mots!R3:R5000) -> 809
A21: 19 | B21: BÂTIMENT | C21: =COUNTA(M1_mots!S3:S5000) -> 936
A22: 20 | B22: PHYSIQUE | C22: =COUNTA(M1_mots!T3:T5000) -> 671
A23: TOTAL | C23: =SUM(C3:C22) -> 14082

Sheet M1_mots
A1: VÊTEMENT | B1: CHASSE ET PECHE | C1: LANGUE | D1: MAMMIFÈRE | E1: TRANSPORT | F1: ÉCONOMIE | G1: SPORT | H1: RELIGION | I1: ÉCOLE | J1: OUTIL ET MÉTIER | K1: POLITIQUE | L1: MUSIQUE | M1: MINÉRAL | N1: MESURE ET INSTRUMENT | O1: ARTISANAT | P1: FRUIT | Q1: ARBRE | R1: MÉDECINE | S1: BÂTIMENT | T1: PHYSIQUE
A2: =COUNTA(A3:A5000) -> 858 | B2: =COUNTA(B3:B5000) -> 905 | C2: =COUNTA(C3:C5000) -> 559 | D2: =COUNTA(D3:D5000) -> 600 | E2: =COUNTA(E3:E5000) -> 803 | F2: =COUNTA(F3:F5000) -> 666 | G2: =COUNTA(G3:G5000) -> 678 | H2: =COUNTA(H3:H5000) -> 691 | ... T2: =COUNTA(T3:T5000) -> 671
A3: ABACA | B3: BLEU | C3: ABAU | D3: ABOYER | E3: ABONNEMENT | F3: ACCUMULER | G3: ACCELERER | H3: ABBAYE | I3: ABSENCE | J3: ACCESSOIRE | K3: ABDICATION | L3: ABOIEMENT | M3: ABRI | N3: ABATTEMENT | O3: ABRASH | P3: ABALONE | Q3: ABATTAGE | R3: ABCES | S3: ABATTOIR | T3: ABDOMEN
A4: ABAYA | B4: ABAIT | C4: ACCENT | D4: ACCOUPLER | E4: ACCELERER | F4: ACHAT | G4: ACROBATIE | H4: ABBE | I4: ACADEMIE | J4: ACCORDEUR | K4: ABDIQUER | L4: ACCORD | M4: ABRUPT | N4: ABORDABLE | O4: ABREGE | P4: ABANDON | Q4: ABATTRE | R4: ABDOMEN | S4: ABBATIAL | T4: ACOUSTIQUE
A5: ACCROC | B5: ABATTIS | C5: ACCENTUER | D5: ADDAX | E5: ACCIDENT | F5: ACQUISE | G5: ACROSPORT | H5: ABBESSE | I5: ACADEMIQUE | J5: ACIER | K5: ABSENT | L5: ACCORDEON | M5: ACAJOU | N5: ABSTINENCE | O5: ACHAT | P5: ABEILLES | Q5: ABEILLE | R5: ABOLIR | S5: ABBAYE | T5: ACTIF
A6: ACETATE | B6: ABATTRE | C6: ACRONYME | D6: AGILE | E6: ACCON | F6: ACQUIT | G6: ACTIF | H6: ABJURER | I6: ADEPTE | J6: ACTEUR | K6: ABSOLU | L6: ACCORDER | M6: ACERBE | N6: ACCALMIE | O6: ACRYLIQUE | P6: ABONDANCE | Q6: ABRICOT | R6: ABSORPTION | S6: ABOUTIR | T6: ACTION
A7: AGLET | B7: ABATURE | C7: ACTE | D7: AGNEAU | E7: ACCOSTER | F7: ACTIF | G7: ACTION | H7: ABLUTION | I7: ADMISSION | J7: ACTIF | K7: ABUS | L7: ACCORDEUR | M7: ACETAMIDE | N7: ACCORDAGE | O7: AFFINAGE | P7: ABONDANTE | Q7: ABRICOTIER | R7: ACADEMIE | T7: ACTIVITE
A8: AGNELIN | B8: ABECHER | C8: ADJECTIF | D8: AGOUTI | E8: ACHEMINER | F8: ACTION | G8: ACTIVITE | H8: ABSIDE | I8: ADRESSE | J8: ACTION | K8: ABUSER | L8: ACOUPHENE | M8: ACIDE | N8: ACETABULE | O8: AGATE | P8: ABRICOT | Q8: ABSINTHE | R8: ACCOUCHEUR | S8: ABRI | T8: ADROIT
A9: AGRAFE | B9: ABLIER | C9: ADVERBE | D9: AGRESTE | E9: ACTIONNER | F9: AFFAIRE | G9: ADVERSAIRE | H9: ABSOLUTION | I9: AGENDA | J9: ACTIVITE | K9: ACCESSION | L9: ACOUSTIQUE | M9: ACIER | N9: ACOUSTIQUE | O9: AGE | P9: ABRICOTIER | Q9: ACACIA | R9: ACCUEIL | S9: ABRIBUS | T9: AFFINITE
A10: AIGUILLE | B10: ABOIEMENT | C10: AFAR | D10: AILE | E10: ADVECTION | F10: AGENCE | G10: AEROBIC | H10: ABSOUDRE | I10: AGENT | J10: ACTUAIRE | K10: ACCORD | L10: ADAGI | M10: ACTINIUM | N10: AFFADIR | O10: AGENCE | P10: ACCAPARER | Q10: ACAJOU | R10: ACCUEILLIR | S10: ABRITER | T10: AGILE
A11: AJOURE | B11: ABOIS | C11: AFFIXE | D11: AISSELLE | E11: AERIEN | F11: AGENT | G11: AGILITE | H11: ABSOUTE | I11: AGREGAT | J11: ADAPTE | K11: ACRATIE | L11: AEROBIC | M11: ACTINOTE | N11: AFFAIBLIR | O11: AGENCEMENT | P11: ACCRA | Q11: ACCROCHER | R11: ACNE | S11: ABSIDE | T11: AGILITE
A12: AJUSTE | B12: ABORDER | C12: AINOU | D12: ALBINOS | E12: AERODYNE | F12: AGIO | G12: AGRIPPER | H12: ABSTENIR | I12: AGREGATIF | J12: AGENCE | K12: ACTION | L12: AFFETTO | M12: ADAMITE | N12: AGENCEMENT | O12: AGRAIRE | P12: ACHARNE | Q12: ADMIRER | R12: ACOUSIE | S12: ACADEMIE | T12: AIR
A13: AJUSTER | B13: ABOYEUR | C13: AKKADIEN | D13: ALLAITER | E13: AEROLITHE | F13: AGIOTAGE | G13: AIKIDO | H13: ABSTINENCE | I13: AGREGATION | J13: AGENT | K13: ACTIVER | L13: AFFUT | M13: ADULAIRE | N13: AIDE | O13: AIGUILLE | P13: ACHETEUR | Q13: AFFOUAGE | R13: ACUPUNCTUR | S13: ACCUEIL | T13: AIRE
A14: ALAISE | B14: ACASTE | C14: ALBANAIS | D14: ALLONGE | E14: AERONEF | F14: AGNEL | G14: AILIER | H14: ACEDIE | I14: AGREGE | J14: AGRONOME | K14: ACTIVISME | L14: AGADA | M14: AEROLITHE | N14: AIGUILLEE | O14: AJOURS | P14: ACIDE | Q14: AGRESTE | R14: ADMINISTRE | S14: ACHEVEMENT | T14: ALBEDO
A15: ALESE | B15: ACCIDENT | C15: ALEMANIQUE | D15: ALOUATE | E15: AEROPLANE | F15: AGREGAT | G15: ALPINISME | H15: ACHOURA | I15: ALPHABET | J15: AIGUILLE | K15: ACTIVISTE | L15: AGITEE | M15: AETITE | N15: AJUSTOIR | O15: ALANDIER | P15: ACIDITE | Q15: AGRICOLE | R15: ADOUCIR | S15: ACIERIE | T15: ALIMENTS
A16: ALPAGA | B16: ACCOUER | C16: ALGIQUE | D16: ALPAGA | E16: AEROPORT | F16: AGRICOLE | G16: AMATEUR | H16: ACOLYTE | I16: ALTERNANCE | J16: ANIMATEUR | K16: ACTUALITE | L16: AGOGO | M16: AGATE | N16: ALCOOMETRE | O16: ALCHIMIE | P16: ACQUET | Q16: AIE | R16: AFFECT | S16: ADOPTION | T16: ALLANT
A17: AMADIS | B17: ACCUL | C17: ALGOL | D17: AMNIOTE | E17: AEROSTAT | F17: AIDE | G17: AMICAL | H17: ADEPTE | I17: ANALYSE | J17: ANIMATION | K17: ADEPTE | L17: AIGU | M17: AIGLE | N17: ALENTIR | O17: ALFA | P17: ACTIONNAIR | Q17: AIRE | R17: AFFECTER | S17: AEROGARE | T17: ALLEGRE
A18: AMIANTE | B18: ACCUSATION | C18: ALGONQUIN | D18: ANDOUILLER | E18: AEROTRAIN | F18: AISANCE | G18: AMORTI | H18: ADHAN | I18: ANALYSER | J18: ANTIQUAIRE | K18: ADHERENT | L18: AILE | M18: AIGRE | N18: ALLEGER | O18: ALLIAGE | P18: AFFURER | Q18: AIRELLE | R18: AFFECTION | T18: ALLIAGE
A19: AMPLE | B19: ACHIGAN | C19: ALINEA | D19: ANE | E19: AIGUILLE | F19: ALENA | G19: AMUSEMENT | H19: ADHESION | I19: ANCIENNE | J19: APICULTEUR | K19: ADHESION | L19: AIR | M19: AIMANT | N19: ALTIMETRE | O19: ALOI | P19: AGNEAU | Q19: AJONC | R19: AGIR | S19: AEROPORT | T19: ALLOTROPIE
A20: ANGLAISE | B20: ACQUER | C20: ALLEMAND | D20: ANGLE | E20: AIR | F20: ALLOCATION | G20: ANNEAUX | H20: ADONAI | I20: ANNALES | J20: APPAREIL | K20: ADJONCTION | L20: ALARME | M20: AIRAIN | N20: ALTO | O20: ALUMINE | P20: AGRICULTEU | Q20: ALGEBRE | R20: AGREGE | S20: AFFINERIE | T20: AME
A21: ANGORA | B21: ADONNER | C21: ALLOPHONE | D21: ANGORA | E21: ALACRITE | F21: ALOI | G21: ANTIDOPAGE | H21: ADORATION | I21: ANNEE | J21: APPARITEUR | K21: ADMISSION | L21: ALBUM | M21: ALBATRE | N21: AMADOUER | O21: AMBRE | P21: AGRICULTUR | Q21: ALISIER | R21: AIDE | S21: AGENCER | T21: AMITIES
A22: ANORAK | B22: AERIEN | C22: ALPHABET | D22: ANIMAL | E22: ALLEGE | F22: ALTERATION | G22: APNEE | H22: ADORER | I22: ANNUAIRE | J22: APPRENTI | K22: ADOPTER | L22: ALLEGRO | M22: ALBITE | N22: AMBRE | O22: AMIDON | P22: AGRUME | Q22: AMANDIER | R22: AIDER | S22: AGORA | T22: AMORPHE
A23: ANTIMITE | B23: AFFUT | C23: ALSACIEN | D23: ANOA | E23: ALLEGRESSE | F23: AMENDE | G23: APNEISTE | H23: ADULATION | I23: APPLIQUER | J23: APTE | K23: ADOPTION | L23: ALTERATION | M23: ALBUGINE | N23: AME | O23: AMPHORE | P23: AIL | Q23: AMARANTE | R23: AIGUILLE | S23: AGRANDIR | T23: AMPERE
A24: APEX | B24: AFFUTER | C24: AMBIGUITE | D24: ANTENNE | E24: ALLURE | F24: AMENDER | G24: APPROPRIE | H24: AFFECTION | I24: APPRENANT | J24: APTITUDE | K24: ADOSSEUR | L24: ALTISTE | M24: ALBUGO | N24: AMORTIR | O24: ANNULAIRE | P24: ALIMENT | Q24: AMI | R24: AIR | S24: AGRICOLE | T24: ANALOGIE
A25: APPARAT | B25: AGRAINAGE | C25: AMHARIQUE | D25: ANTILOPE | E25: ALPINE | F25: AMORTIR | G25: AQUAGYM | H25: AGAPE | I25: APPRENDRE | J25: ARBITRE | K25: ADRESSE | L25: ALTO | M25: ALCALIN | N25: AMPERE | O25: ANTIMOINE | P25: ALKEKENGE | Q25: ANA | R25: AJUSTER | S25: ALCAZAR | T25: ANALYSE
A26: APPRET | B26: AGRENER | C26: ANATOMIE | D26: APPAT | E26: AMBULANCE | F26: AMPLEUR | G26: AQUAPLANE | H26: AGNOSTIQUE | I26: APPRENTI | J26: ARCHER | K26: ADROIT | L26: AMATI | M26: ALFENIDE | N26: AMPHORE | O26: APPLIQUER | P26: AMASSER | Q26: ARBORISTE | R26: ALCALOIDE | S26: ALE | T26: ANDROGYNE
A27: ARAMIDE | B27: AGRES | C27: ANAUDIE | D27: ARBORICOLE | E27: AMENAGE | F27: ANALYSE | G27: ARBALETE | H27: AMBON | I27: ARCHIVES | J27: ARCHET | K27: AFFAIRE | L27: AMBIANCE | M27: ALGUE | N27: AMPLEUR | O27: APPRENTI | P27: AMBITION | Q27: ARBOUSIER | R27: ALIENE | S27: ALLEE | T27: ANGLE
A28: ARCHAL | B28: AGRIFFER | C28: ANDINE | D28: ARETE | E28: AMPHIBIE | F28: ANALYSTE | G28: ARBITRAL | H28: AME | I28: ARGUMENTER | J28: ARCHITECTE | K28: AFFILIE | L28: AMPLE | M28: ALKALI | N28: ANA | O28: APPRET | P28: AMER | Q28: ARBRE | R28: ALIENISTE | S28: ALUNERIE | T28: ANIMAL
A29: ARMELINE | B29: AGUET | C29: ANDOKE | D29: ARRACHE | E29: ANE | F29: ANNALITE | G29: ARBITRE | H29: AMEN | I29: ART | J29: ARCHIVISTE | K29: AFFINITE | L29: AMPLI | M29: ALLOPHANE | N29: ANCRE | O29: ARCATURE | P29: AMINE | Q29: ARBUSTE | R29: ALLAITER | S29: AMBASSADE | T29: ANIMALES
A30: ARMET | B30: AGUICHER | C30: ANGLAIS | D30: ARRONDI | E30: ANGEVIN | F30: ANNUEL | G30: ARCHER | H30: AMIDA | I30: ARTICLE | J30: ARMURIER | K30: AGENCE | L30: AMPLIFIER | M30: ALMANDIN | N30: ANGLE | O30: ARCHE | P30: ANACARDIER | Q30: ARDENNE | R30: ALLERGIE | S30: AMBITIEUX | T30: ANIMER
A31: ARMOIRE | B31: AIGLEFIN | C31: ANGLOPHONE | D31: ATELE | E31: ANNEXE | F31: ANNUITE | G31: ARCHERIE | H31: AMISH | I31: ARTISTE | J31: ARRIMEUR | K31: AGILITE | L31: ANDALOUX | M31: ALMELEC | N31: ANGSTROM | O31: ARGENT | P31: ANANAS | Q31: ARGAN | R31: ALLOPATHE | S31: AMBITION | T31: ANNULAIRE
A32: ARMURE | B32: AIM | C32: ANTONYME | D32: ATTACHE | E32: ARBORER | F32: APPOINT | G32: ARENE | H32: AMOUR | I32: ASSIDU | J32: ARROSEUR | K32: AGITATION | L32: ANDANTE | M32: ALPAX | N32: ANNEE | O32: ARGENTURE | P32: API | Q32: ARGANIER | R32: ALLOPATHIE | S32: AMBULANCE
A33: ASTRAKAN | B33: AIN | C33: APEX | D33: AUROCHS | E33: ARCHE | F33: APPORT | G33: ARRIERE | H33: ANAGOGIE | I33: ASSIDUITE | J33: ART | K33: AGITER | L33: APPEAU | M33: ALPINISME | N33: ANNUEL | O33: ARGILE | P33: ARACHIDE | Q33: ARMURE | R33: ALVEOLE | S33: AMENAGER | T33: APPARENCE
A34: ATELIER | B34: ALAI | C34: APHASIE | D34: AVAHI | E34: ARMATEUR | F34: APPORTEUR | G34: ARTISTE | H34: ANATHEME | I34: ATELIER | J34: ARTISAN | K34: AGORA | L34: ARCHET | M34: ALTERITE | N34: APAISER | O34: ARGUE | P34: ARBOUSIER | Q34: ASPIC | R34: ALZHEIMER | S34: AMENDER | T34: APPDIGEST
A35: ATOUR | B35: ALAN | C35: APHONE | D35: AVANT | E35: ARPEGE | F35: ARGENT | G35: ATEMI | H35: ANCETRE | I35: ATLAS | J35: ARTISANAL | K35: AGRARIEN | L35: ARCON | M35: ALUMINE | N35: APERCU | O35: ARMURE | P35: ARBRE | Q35: AUBEPINE | R35: AMADOUER | S35: AMIENOISE | T35: APPOINT
A36: BABOUCHE | B36: ALEVIN | C36: APHONIE | D36: BABIROUSSA | E36: ARRET | F36: ARGENTIER | G36: ATHLETE | H36: ANGE | I36: ATTENTION | J36: ARTISANAT | K36: AGREGATION | L36: ARGOL | M36: ALUMINITE | N36: APPAREIL | O36: ARMURIER | P36: ARBUSTE | Q36: AULNE | R36: AMBULANCE | S36: AMIRAUTE | T36: APTE
A37: BACHE | B37: ALGUE | C37: APHTE | D37: BABOUIN | E37: ARROSEUSE | F37: ARPAILLEUR | G37: ATHLETIQUE | H37: ANGELOT | I37: AUTEUR | J37: ARTISTE | K37: AGREMENT | L37: ARIA | M37: ALUMINIUM | N37: APPEAU | O37: ART | P37: ARGENT | Q37: AUNE | R37: AMBULANCIE | S37: AMPHIBIE | T37: APTITUDE
A38: BALLERINE | B38: ALOSE | C38: APOSTROPHE | D38: BAI | E38: ARTERE | F38: ARRERAGES | G38: ATHLETISME | H38: ANGLICAN | I38: AUTORITE | J38: ASSIDU | K38: ALIENATION | L38: ARIETTE | M38: ALUN | N38: APTITUDE | O38: ARTIFICE | P38: ARILLE | Q38: AUTOMNE | S38: ANCIEN
A39: BALLET | B39: ALOSIER | C39: ARABE | D39: BAIJI | E39: ASCENSEUR | F39: ARRIERE | G39: ATTAQUANT | H39: ANIMISME | I39: AVIS | J39: ASSIDUITE | K39: ALLIAGE | L39: ARPEGE | M39: ALUNITE | N39: ARBITRAGE | O39: ARTISAN | P39: ARISTOCRAT | Q39: AVELINE | R39: AMELIORER | S39: ANIMALERIE | T39: ARISTOTE
A40: BANANE | B40: AMARRE | C40: ARGOT | D40: BALEINE | E40: ASTRONEF | F40: ARRIMAGE | G40: ATTELAGE | H40: ANIMISTE | I40: BAC | J40: ASSISTANT | K40: ALLIANCE | L40: ARRANGEUR | M40: AMBRE | N40: ARCHET | O40: ARTISANAL | P40: AROMATIQUE | Q40: AVOCAT | R40: AMINE | S40: ANNEXE | T40: ASPECT
...

Sheet M2
A1: ALKAMO — M2
A2: N° | B2: THÈME | C2: MOTS
A3: 1 | B3: MARINE | C3: =COUNTA(M2_mots!A3:A5000) -> 701
A4: 2 | B4: CHIMIE | C4: =COUNTA(M2_mots!B3:B5000) -> 804
A5: 3 | B5: COUTURE | C5: =COUNTA(M2_mots!C3:C5000) -> 826
A6: 4 | B6: GRAMMAIRE | C6: =COUNTA(M2_mots!D3:D5000) -> 598
A7: 5 | B7: FLEUR | C7: =COUNTA(M2_mots!E3:E5000) -> 603
A8: 6 | B8: INDUSTRIE | C8: =COUNTA(M2_mots!F3:F5000) -> 659
A9: 7 | B9: MÉTIER | C9: =COUNTA(M2_mots!G3:G5000) -> 1214
A10: 8 | B10: ANIMAL | C10: =COUNTA(M2_mots!H3:H5000) -> 549
A11: 9 | B11: CUISINE | C11: =COUNTA(M2_mots!I3:I5000) -> 720
A12: 10 | B12: INSTITUTION | C12: =COUNTA(M2_mots!J3:J5000) -> 756
A13: 11 | B13: OUTIL | C13: =COUNTA(M2_mots!K3:K5000) -> 779
A14: 12 | B14: PÉDAGOGIE | C14: =COUNTA(M2_mots!L3:L5000) -> 783
A15: 13 | B15: JEU | C15: =COUNTA(M2_mots!M3:M5000) -> 739
A16: 14 | B16: ART ET MUSIQUE | C16: =COUNTA(M2_mots!N3:N5000) -> 855
A17: 15 | B17: ASTRONOMIE | C17: =COUNTA(M2_mots!O3:O5000) -> 601
A18: 16 | B18: ALIMENT | C18: =COUNTA(M2_mots!P3:P5000) -> 743
A19: 17 | B19: BOTANIQUE | C19: =COUNTA(M2_mots!Q3:Q5000) -> 996
A20: 18 | B20: ÉNERGIE | C20: =COUNTA(M2_mots!R3:R5000) -> 754
A21: 19 | B21: PUISSANCE | C21: =COUNTA(M2_mots!S3:S5000) -> 612
A22: 20 | B22: ANATOMIE | C22: =COUNTA(M2_mots!T3:T5000) -> 882
A23: TOTAL | C23: =SUM(C3:C22) -> 15174

Sheet M2_mots
A1: MARINE | B1: CHIMIE | C1: COUTURE | D1: GRAMMAIRE | E1: FLEUR | F1: INDUSTRIE | G1: MÉTIER | H1: ANIMAL | I1: CUISINE | J1: INSTITUTION | K1: OUTIL | L1: PÉDAGOGIE | M1: JEU | N1: ART ET MUSIQUE | O1: ASTRONOMIE | P1: ALIMENT | Q1: BOTANIQUE | R1: ÉNERGIE | S1: PUISSANCE | T1: ANATOMIE
A2: =COUNTA(A3:A5000) -> 701 | B2: =COUNTA(B3:B5000) -> 804 | C2: =COUNTA(C3:C5000) -> 826 | D2: =COUNTA(D3:D5000) -> 598 | E2: =COUNTA(E3:E5000) -> 603 | F2: =COUNTA(F3:F5000) -> 659 | G2: =COUNTA(G3:G5000) -> 1214 | H2: =COUNTA(H3:H5000) -> 549 | ... T2: =COUNTA(T3:T5000) -> 882
A3: ABER | B3: ACCUM | C3: ABEILLE | D3: ABECEDAIR | E3: ABEILLE | F3: ABATTOIR | G3: ABATTEUR | H3: ABATTAGE | I3: ABAISSE | J3: ABOLITION | K3: ACCOMPAGNE | L3: ABECEDAIR | M3: ACADEMIE | N3: ABSTRAIT | O3: ABSIDE | P3: ABECQUER | Q3: ABELIA | R3: ABATTAGE | S3: ABATTRE | T3: ABCES
A4: ABORD | B4: ACETAMIDE | C4: ABLATION | D4: ABLATIF | E4: ABRUTIR | F4: ABRASION | G4: ABOYEUR | H4: ABATTOIR | I4: ABAISSER | J4: ACADEMIE | K4: ACCORD | L4: ABREGE | M4: ACCESSOIRE | N4: ACADEMISME | O4: ACCOMPLIR | P4: ABONDANCE | Q4: ABELIE | R4: ABSORPTION | T4: ABDOMEN
A5: ABORDAGE | B5: ACETATE | C5: ACADEMIE | D5: ABREVIATIO | E5: ABSINTHE | F5: ACHAT | G5: ACCONIER | H5: ABEILLE | I5: ABAT | J5: ACADEMIQUE | K5: ACCORDEUR | L5: ACADEMIE | M5: ACCORD | N5: ACCORD | O5: ACCRETION | P5: ABONDANTE | Q5: ABOUTA | R5: ACCELERATE | S5: ACCESSION | T5: ABDOMINAL
A6: ABORDER | B6: ACETONE | C6: ACCESSOIRE | D6: ABSTRAIT | E6: ACACIA | F6: ACIDE | G6: ACHETEUR | H6: ABRUPT | I6: ABATTIS | J6: ACCOMMODER | K6: ACCORDOIR | L6: ACCOMPAGNE | M6: ACQUISITIO | N6: ACCORDAGE | O6: ACRAB | P6: ABRITER | Q6: ABSCISSION | S6: ACCULER | T6: ABDUCTEUR
A7: ABRI | B7: ACETYLENE | C7: ACCLAME | D7: ACADEMIE | E7: ACANTHE | F7: ACIER | G7: ACIERISTE | H7: AGIR | I7: ABERDEEN | J7: ACCORD | K7: ACIER | L7: ACCUEIL | M7: ACTEUR | N7: ACCORDEON | O7: ACTEUR | P7: ABSORBER | Q7: ACANTHE | R7: ACCUMULATE | S7: ACHEMINER | T7: ACADEMIE
A8: ABYSSAL | B8: ACIDE | C8: ACCOUCHEME | D8: ACCENT | E8: ACANTHES | F8: ACIERIE | G8: ACONIER | H8: AGRESSIF | I8: ABRICOT | J8: ACCUEIL | K8: ACTE | L8: ACQUERIR | M8: ACTION | N8: ACCORDEUR | O8: ACTIVITE | P8: ABSTINENCE | Q8: ACARIEN | R8: ACHAT | S8: ACIER | T8: ACANTHE
A9: ACCALMIE | B9: ACIER | C9: ACCROC | D9: ACCEPTION | E9: ACHILLEE | F9: ACRYLIQUE | G9: ACQUERIR | H9: AGRESSIVIT | I9: ACCRA | J9: ACHEMINER | K9: AFFUTER | L9: ACQUIS | M9: ACTIONNAIR | N9: ACCROCHE | O9: AERODYNE | P9: ACIDE | Q9: ACCLIMATAT | R9: ACHETER | S9: ACQUERIR | T9: ACETABULE
A10: ACCOSTAGE | B10: ACRYLIQUE | C10: ACCROCHE | D10: ACCORD | E10: ACTEE | F10: ACTIF | G10: ACROBATE | H10: AGRESTE | I10: ACCUEIL | J10: ACTE | K10: AIGUILLE | L10: ACQUISITIO | M10: ADAPTATEUR | N10: ACHROME | O10: AEROLITE | P10: ACIDITE | Q10: ACIDE | R10: ACRETE | S10: ACTE | T10: ACINI
A11: ACCOSTER | B11: ACTINIUM | C11: ACETATE | D11: ACCUSATIF | E11: AGAPANTHE | F11: ACTIVITE | G11: ACTEUR | H11: AIGLE | I11: ACERBE | J11: ACTES | K11: AIR | L11: ACTIVE | M11: ADAPTATIVE | N11: ACORDE | O11: AGIR | P11: ACTIF | Q11: ACOELOMATE | R11: ACTINIDE | S11: ACTION | T11: ADAPTATIF
A12: ACTUAIRE | B12: ACTINOTE | C12: ACRYLIQUE | D12: ACRONYME | E12: AGASTACHE | F12: ADAPTATION | G12: AEDE | H12: AIGRETTE | I12: ACHARD | J12: ACTION | K12: AISSETTE | L12: ACTIVITE | M12: ADDICTIF | N12: ACTE | O12: AGO | P12: ACTUALISER | Q12: ACTINIDIE | R12: ACTION | S12: ACUITE | T12: ADAPTEE
A13: AERIEN | B13: ACTIVATION | C13: ADMIRATION | D13: ACTANT | E13: AGAVE | F13: ADDITIF | G13: AERONAUTE | H13: AIR | I13: ACRA | J13: ACTUAIRE | K13: ALENE | L13: ADEPTE | M13: ADOPTER | N13: ACTEUR | O13: AIR | P13: ADDITIF | Q13: ADAPTATION | R13: ACTIONNEUR | S13: ADMINISTRE | T13: ADDUCTEUR
A14: AERONEF | B14: ADAMANTIN | C14: AGRAFE | D14: ACTE | E14: AGE | F14: ADJUVANT | G14: AEROSTIER | H14: ALBATROS | I14: AFFAME | J14: ADAPTEE | K14: ALESOIR | L14: ADMISSION | M14: ADVERSAIRE | N14: ACTIVITES | O14: AKARNAR | P14: AFFAME | Q14: ADAXIALE | R14: ACTIVITE | S14: ADVERSAIRE | T14: ADNEE
A15: AFFINER | B15: ADAMITE | C15: AGRAFURE | D15: ACTIF | E15: AGRIMOINE | F15: ADROIT | G15: AFFICHEUR | H15: ALIMENTAIR | I15: AGAPE | J15: ADHESION | K15: ALIDADE | L15: ADOLESCENT | M15: ADVERSE | N15: ACTRICE | O15: ALBEDO | P15: AFFOURAGER | Q15: ADRAGANT | R15: ADDITION | S15: AFFAIBLISS | T15: ADRENALINE
A16: AFFRETER | B16: ADULAIRE | C16: AIGUILLE | D16: ADJECTIF | E16: AINES | F16: AFFAIRE | G16: AFFILEUR | H16: ALLIGATOR | I16: AGNEAU | J16: ADJOINT | K16: ALTO | L16: ADOPTER | M16: AERIEN | N16: ACTUALITE | O16: ALBENE | P16: AGAPE | Q16: AGRICULTUR | R16: ADYNAMIE | S16: AGENT | T16: AILE
A17: AFFRETEUR | B17: AEGYRINE | C17: AIGUILLEE | D17: ADJECTIVAL | E17: AIR | F17: AFFINAGE | G17: AFFILOIR | H17: ALPAGA | I17: AIGRE | J17: ADMINISTRA | K17: AMPEREMETR | L17: ADULTE | M17: AFFICHAGE | N17: ADAGIO | O17: ALCOR | P17: AGAR | Q17: AGRION | R17: AGENCE | S17: AGILITE | T17: AINE
A18: AIRE | B18: AEROSOL | C18: AISANCE | D18: ADJONCTION | E18: AISSELLE | F18: AGENCEMENT | G18: AFFINEUR | H18: ALTRUISTE | I18: AIL | J18: ADMINISTRE | K18: ANALYSE | L18: AFFICHE | M18: ALEATOIRE | N18: ADMIRATEU | O18: ALGOL | P18: AGNEAU | Q18: AGRONOMIE | R18: AGILITE | S18: AGIR | T18: AISSELLE
... A22: ALLURE | B22: AIMANT | C22: AJOURER | D22: ADVERBE | E22: ALOE | F22: AIGUISER | G22: AFFUTEUR | H22: ANIMAL | I22: ALIGOT | J22: AGENCEMENT | K22: ANGLE | L22: AGREGE | M22: AMATEUR | N22: AEROBIC | O22: ALPHA | P22: AGRICULTUR | Q22: AILE | R22: ALIMENT | S22: AIDE | T22: AMPHITHEAT
A23: ALOSE | B23: AIR | C23: AJUSTE | D23: ADVERBIAL | E23: AMANDIER | F23: AIR | G23: AGENCIER | H23: ANIMALERIE | I23: ALIMENT | J23: AGENCER | K23: APPAREIL | L23: AGREMENT | M23: AMBIANCE | N23: AEROGRAPHE | O23: ALTAZIMUTH | P23: AGROALIMEN | Q23: AKENE | S23: AIRAIN | T23: AMYGDALE
A24: AMARINER | B24: AIRAIN | C24: AJUSTER | D24: AFFINITE | E24: AMARANTE | F24: ALARME | G24: AGENT | H24: ANIMALITE | I24: ALIMENTAIR | J24: AGENT | K24: APPAREILLA | L24: ALBUM | M24: AMICAL | N24: AFFICHE | O24: ALTIMETRE | P24: AIDE | Q24: ALATERNE | R24: ALIMENTER | S24: ALLIANCE | T24: AMYLASE
A25: AMARRAGE | B25: ALABANDINE | C25: ALLURE | D25: AFFIXE | E25: AMARYLLIS | F25: ALCOOL | G25: AGIOTEUR | H25: ANTHROPOPH | I25: ALIMENTER | J25: AGREE | K25: APPLICATIO | L25: ALLAITEMEN | M25: AMPHITHEAT | N25: AGON | O25: ALTITUDE | P25: AIL | Q25: ALBINOS | R25: ALLANT | S25: ALLIANCES | T25: ANAGLYPHE
A26: AMARRE | B26: ALABANDITE | C26: ALPAGA | D26: AGRAMMATIC | E26: AMITIE | F26: ALESAGE | G26: AGREEUR | H26: ANTILOPE | I26: ALLEGE | J26: AGRICOLE | K26: ARATOIRE | L26: ALPHABETIS | M26: AMUSANT | N26: AIKIDO | O26: ALUNIR | P26: ALCOOL | Q26: ALBIZZIA | R26: ALLEGRESSE | S26: ALLIE | T26: ANAL
A27: AMARRES | B27: ALBATRE | C27: AMBULATOIR | D27: AGRAMMATIS | E27: AMMI | F27: ALESOIR | G27: AIDE | H27: APPETIT | I27: ALMANACH | J27: AJUSTER | K27: ARME | L27: AMI | M27: AMUSEMENT | N27: AIR | O27: ALYCONE | P27: ALGUE | Q27: ALBUMINE | R27: ALLUMAGE | S27: ALLURE | T27: ANALYSE
A28: AME | B28: ALBITE | C28: AMIDONNER | D28: AGREGATION | E28: AMSONIE | F28: ALFA | G28: AIDEAU | H28: APPRIVOIS | I28: ALOYAU | J28: ALIGNER | K28: ARRACHECLO | L28: AMIE | M28: AMUSER | N28: AISANCE | O28: AMAS | P28: ALGUES | Q28: ALEURITE | R28: ALTERNATEU | S28: AMBITION | T28: ANATOMIE
A29: AMER | B29: ALBUGINE | C29: AMPUTATION | D29: AKKADIEN | E29: ANCOLIE | F29: ALIMENT | G29: AIGUISEUR | H29: APTITUDE | I29: AMANDE | J29: ALINEA | K29: ASSORTIME | L29: AMITIE | M29: ANALYSER | N29: ALBUM | O29: AMATEUR | P29: ALIMENT | Q29: ALGOIDE | R29: AME | S29: AME | T29: ANATOMIQUE
A30: AMIRAL | B30: ALBUGO | C30: ANATOMIE | D30: ALLATIF | E30: ANDROCEE | F30: ALIMENTER | G30: AIGUISOIR | H30: AQUATIQUE | I30: AMIDON | J30: ALLIANCE | K30: ASTRE | L30: AMPHI | M30: ANIMATEUR | N30: ALCHIMIE | O30: ANALEMME | P30: ALIMENTAIR | Q30: ALGUE | R30: AMORTISSEM | S30: AMNISTIE | T30: ANATOMISER
A31: AMONT | B31: ALCALI | C31: ANATOMISTE | D31: ALLOMORPHE | E31: ANEMONE | F31: ALLIAGE | G31: AISSEAU | H31: ARAIGNEE | I31: AMUSE | J31: ALLOCATION | K31: ASTROLABE | L31: ANALPHABET | M31: ANIMER | N31: ALLEGORIE | O31: ANGLE | Q31: ALIBOUFIER | R31: AMPACITE | S31: AMPLEUR | T31: ANATOMISTE
A32: ANCHOIS | B32: ALCALIN | C32: ANESTHESIE | D32: ALPHABET | E32: ANTHERE | F32: ALLUMETTE | G32: AJUSTEUR | H32: ARCHETYPE | I32: ANCHOIS | J32: AMBASSADE | K32: ATELIER | L32: ANALYSE | N32: ALLEGRO | O32: ANNEAU | P32: ALIMENTER | Q32: ALIMENT | R32: AMPERAGE | S32: AMPLIFICAT | T32: ANGIOGRAPH
A33: ANCRAGE | B33: ALCALINITE | C33: ANGORA | D33: ALTERNANCE | E33: ANTHURIUM | F33: ALUMINIUM | G33: ALCADE | H33: ARTHROPODE | I33: ANDOUILLET | J33: AMENAGEMEN | K33: ATTIRAIL | L33: ANGE | M33: ANTICIPER | N33: ALTO | O33: ANNEE | P33: ALLAITEMEN | Q33: ALIMENTS | R33: AMPERE | S33: AMPLIFIER | T33: ANIMAL
A34: ANCRE | B34: ALCANE | C34: APIECEUR | D34: AMBIGUITE | E34: ARBRE | F34: ALUNERIE | G34: ALCOOLIER | H34: ASSOUVIR | I34: ANETH | J34: ANALYSE | K34: ATTISOIR | L34: ANIMATEUR | M34: APPROCHE | N34: AMATEUR | O34: ANTARES | P34: ALLAITER | Q34: ALLEE | R34: ANIMATION | S34: AMPLITUDE | T34: ANNEAU
A35: ANGLE | B35: ALCANES | C35: APLAT | D35: AMIM | E35: ARBRISSEAU | F35: AMBRE | G35: ALESEUR | H35: AUTOMATIQU | I35: ANIS | J35: ANARCHIE | K35: BAGAGE | L35: ANIMER | M35: ARBITRAGE | N35: AMBITION | O35: ANTENNE | P35: ALLERGIE | Q35: ALLIER | R35: ANION | S35: AMPOULE | T35: ANNEXE
A36: ANNEXE | B36: ALCENE | C36: APPARENCE | D36: AMORPHE | E36: ARBUSTE | F36: AMIDON | G36: ALESOIR | H36: AUTOUR | I36: APERITIF | J36: ANARCHISME | K36: BALANCE | L36: ANNONCER | M36: ARBITRE | N36: ANDANTE | O36: APEX | P36: AMANDE | Q36: ALOE | R36: ANODE | S36: ANARCHIE | T36: ANNULAIRE
A37: ANSE | B37: ALCHIMIE | C37: APPLIQUE | D37: ANAGRAMME | E37: AREOLE | F37: AMORCE | G37: ALFATIER | H37: AUTRUCHE | I37: APPRENTI | J37: ANATOMIQUE | K37: BALANCIER | L37: APPRENANT | M37: ARBITRER | N37: ANIMATEUR | O37: APHELIE | P37: AMBROISIE | Q37: ALOES | R37: APATHIE | S37: ANEANTIR | T37: ANSE
A38: ANTENNE | B38: ALCHIMISTE | C38: APPRET | D38: ANALOGIE | E38: ARGANIER | F38: AMORTIR | G38: ALIENISTE | H38: AYE | I38: ARGENT | J38: ANIMER | K38: BALAYETTE | L38: APPRENDRE | M38: ARCADE | N38: ANTILABE | O38: APHELION | P38: AMER | Q38: ALOUCHIER | R38: APATHIQUE | S38: ANGE | T38: ANTERIEUR
A39: APPAT | B39: ALCOOL | C39: ARMATURE | D39: ANALYSE | E39: ARGENTE | F39: AMPHORE | G39: ALISIER | H39: BABOUIN | I39: ARMOIRE | J39: APPRETER | K39: BANJO | L39: APPRENTI | M39: ARENE | N39: ANTIQUE | O39: APOASTRE | P39: AMIDON | Q39: ALPAGA | R39: APLOMB | S39: ANNEXION | T39: ANTHELIX
A40: AQUATIQUE | B40: ALDEHYDE | C40: ARRET | D40: ANALYSEUR | E40: ARMOISE | F40: AMPOULE | G40: ALPINISTE | H40: BALEINE | I40: AROMATE | J40: ARBITRAIRE | K40: BARBE | L40: APPRENTIE | M40: ARGENT | N40: ANTIQUITE | O40: APOGEE | P40: AMITIE | Q40: ALPIN | R40: APPROVISIO | S40: ANODE | T40: ANTHROPOLO
A41: ARCHIPEL | B41: ALDEHYDES | C41: ARRONDI | D41: ANALYSTE | E41: ARNICA | F41: ANALYSE | G41: ALTISTE | H41: BALOURD | I41: AROMATIQUE | K41: BAROMETRE | L41: APPROCHE | M41: ARMEE | N41: APARTE | O41: APOLLO | P41: AMORCER | Q41: ALPINE | R41: APRETE | S41: APOGEE | T41: ANTHROPOME
A42: ARCTIQUE | B42: ALGEBRE | C42: ARTISANAL | D42: ANAPHORE | E42: AROME | F42: APTE | G42: AMATEUR | H42: BANDICOOT | I42: AROME | K42: BAROQUE | L42: APPROPRIA | M42: ASSEMBLER | N42: AQUARELLE | O42: APOLUNE | P42: AMPLIFICAT | Q42: ALTEA | R42: APTE | S42: ARBITRAGE | T42: ANTHROPOTO
A43: ARISER | B43: ALIZARINE | C43: ARTISANAT | D43: ANASTROPHE | E43: ARROSER | F43: ARGENT | G43: ANALYSTE | H43: BARBARE | I43: ART | J43: ARCHIVE | K43: BARRE | L43: APTITUDE | M43: ASTUCE | N43: ARABESQUE | O43: APPARENTE | P43: ANIMAL | Q43: AMARANTE | R43: APTITUDE | S43: ARDEUR | T43: ANTICORPS
...

Sheet M3
A1: ALKAMO — M3
A2: N° | B2: THÈME | C2: MOTS
A3: 1 | B3: JEU ET SPORT | C3: =COUNTA(M3_mots!A3:A5000) -> 1180
A4: 2 | B4: TEMPS ET MÉTÉO | C4: =COUNTA(M3_mots!B3:B5000) -> 564
A5: 3 | B5: INFORMATIQUE | C5: =COUNTA(M3_mots!C3:C5000) -> 1167
A6: 4 | B6: MATHÉMATIQUES | C6: =COUNTA(M3_mots!D3:D5000) -> 940
A7: 5 | B7: AGRICULTURE | C7: =COUNTA(M3_mots!E3:E5000) -> 787
A8: 6 | B8: ART | C8: =COUNTA(M3_mots!F3:F5000) -> 971
A9: 7 | B9: NAVIGATION | C9: =COUNTA(M3_mots!G3:G5000) -> 1093
A10: 8 | B10: FAUNE ET FLORE | C10: =COUNTA(M3_mots!H3:H5000) -> 951
A11: 9 | B11: GUERRE | C11: =COUNTA(M3_mots!I3:I5000) -> 735
A12: 10 | B12: ADMINISTRATION | C12: =COUNTA(M3_mots!J3:J5000) -> 1081
A13: 11 | B13: FAMILLE | C13: =COUNTA(M3_mots!K3:K5000) -> 448
A14: 12 | B14: PHYSIQUE ET CHIMIE | C14: =COUNTA(M3_mots!L3:L5000) -> 1456
A15: 13 | B15: PAYS ET CAPITALES | C15: =COUNTA(M3_mots!M3:M5000) -> 819
A16: 14 | B16: MÉDECINE ET ANATOMIE | C16: =COUNTA(M3_mots!N3:N5000) -> 1575
A17: 15 | B17: COMMERCE | C17: =COUNTA(M3_mots!O3:O5000) -> 1019
A18: 16 | B18: DROIT ET JUSTICE | C18: =COUNTA(M3_mots!P3:P5000) -> 703
A19: 17 | B19: LITTÉRATURE | C19: =COUNTA(M3_mots!Q3:Q5000) -> 649
A20: 18 | B20: TOURISME | C20: =COUNTA(M3_mots!R3:R5000) -> 471
A21: 19 | B21: URBANISME | C21: =COUNTA(M3_mots!S3:S5000) -> 628
A22: 20 | B22: MER ET OCÉAN | C22: =COUNTA(M3_mots!T3:T5000) -> 1152
A23: TOTAL | C23: =SUM(C3:C22) -> 18389

Sheet M3_mots
A1: JEU ET SPORT | B1: TEMPS ET MÉTÉO | C1: INFORMATIQUE | D1: MATHÉMATIQUES | E1: AGRICULTURE | F1: ART | G1: NAVIGATION | H1: FAUNE ET FLORE | I1: GUERRE | J1: ADMINISTRATION | K1: FAMILLE | L1: PHYSIQUE ET CHIMIE | M1: PAYS ET CAPITALES | N1: MÉDECINE ET ANATOMIE | O1: COMMERCE | P1: DROIT ET JUSTICE | Q1: LITTÉRATURE | R1: TOURISME | S1: URBANISME | T1: MER ET OCÉAN
A2: =COUNTA(A3:A5000) -> 1180 | B2: =COUNTA(B3:B5000) -> 564 | C2: =COUNTA(C3:C5000) -> 1167 | D2: =COUNTA(D3:D5000) -> 940 | E2: =COUNTA(E3:E5000) -> 787 | F2: =COUNTA(F3:F5000) -> 971 | G2: =COUNTA(G3:G5000) -> 1093 | H2: =COUNTA(H3:H5000) -> 951 | ... T2: =COUNTA(T3:T5000) -> 1152
A3: ACADEMIE | B3: ABAS | C3: ABSTRAIT | D3: ABAQUE | E3: ABATTOIR | F3: ABSTRAIT | G3: ABATEE | H3: ABATTAGE | I3: ABRI | J3: ABATTEMENT | K3: ACCUEIL | L3: ABDOMEN | M3: ABDIQUER | N3: ABCES | O3: ABATAGE | P3: ABROGATION | Q3: ABSTRACTIO | R3: ABRI | S3: ABRI | T3: ABATEE
A4: ACCESSOIRE | B4: ABAT | C4: ACADEMIE | D4: ABELIEN | E4: ABLAIS | F4: ACADEMISME | G4: ABER | H4: ABATTOIR | I4: ACADEMIE | J4: ABOLITION | K4: ADOLESCENC | L4: ACCUM | M4: ABIDJAN | N4: ABDOMEN | O4: ACCORD | P4: ABSOLUTION | Q4: ABSTRAIT | R4: ACCUEIL | S4: ABRIBUS | T4: ABER
A5: ACCORD | B5: ABONDANCE | C5: ACCES | D5: ABSCISSE | E5: ABOITEAU | F5: ACCORD | G5: ABORD | H5: ABBAYE | I5: ACCORD | J5: ABROGER | K5: ADOLESCENT | L5: ACETAMIDE | M5: ACCORD | N5: ABDOMINAL | O5: ACCORDER | P5: ABUS | Q5: ACADEMICIE | R5: ACCUEILS | S5: ABSIDE | T5: ABORD
A6: ACQUISITIO | B6: ABONDANTE | C6: ACCUEIL | D6: ABSOLUE | E6: ABRICOT | F6: ACCORDAGE | G6: ABORDAGE | H6: ABEILLE | I6: ACHARNE | J6: ABSOLU | K6: ADOPTER | L6: ACETATE | M6: ACCRA | N6: ABDUCTEUR | O6: ACCUMULER | P6: ABUSUS | Q6: ACADEMISME | R6: AEROPORT | S6: ACCROISSEM | T6: ABORDAGE
A7: ACROBATIE | B7: ABRI | C7: ACTIVATION | E7: ABUSER | F7: ACCORDEON | G7: ABORDER | H7: ABRUPT | I7: ACHARNEMEN | J7: ABUS | K7: ADOPTIF | L7: ACETONE | M7: ACCREDITE | N7: ABOLIR | O7: ACHAT | P7: ACCEDIT | Q7: ACCENT | R7: AFFLUENT | S7: ACCROTERE | T7: ABORDER
A8: ACROSPORT | B8: ABRITER | C8: ACTIVER | D8: ABSTRAITE | E8: ACARIOSE | F8: ACCORDEUR | G8: ABRI | H8: ACACIA | I8: ACHEEN | J8: ABUSIF | K8: ADOPTION | L8: ACETYLENE | M8: ACCUEILLIR | N8: ABSORPTION | O8: ACHETER | P8: ACCENSE | Q8: ACCESSOIRE | R8: AFFLUT | S8: ACIER | T8: ABRI
A9: ACTEUR | B9: ABSOLU | C9: ACTUALISER | D9: ABSURDE | E9: ACMEE | F9: ACCROCHE | G9: ABYSSAL | H9: ACAJOU | I9: ACIER | J9: ACADEMIE | K9: ADOPTIVE | L9: ACIDE | M9: ACHGABAT | N9: ACADEMIE | O9: ACHETEUR | P9: ACCORD | Q9: ACROSTICHE | R9: AFFLUX | S9: ACROPOLE | T9: ABYSSAL
A10: ACTIF | B10: ACCALMIE | C10: ADAPTATEUR | D10: ACUTANGLE | E10: ACREAGE | F10: ACHROME | G10: ACCALMIE | H10: ACANTHE | I10: ACTION | J10: ACADEMIQUE | K10: ADULTE | L10: ACIER | M10: ADDIS | N10: ACANTHE | O10: ACOMPTE | P10: ACCUSATION | Q10: ACTE | R10: AGENCE | S10: AEROPORT | T10: ACCALMIE
A11: ACTION | C11: ADRESSE | D11: ADDITION | E11: ACTIVITE | F11: ACORDE | G11: ACCONAGE | H11: ADAPTATION | I11: ACTIVISTE | J11: ACCIDENT | K11: AFFECTION | L11: ACOUSTIQUE | M11: ADRESSE | N11: ACCOUCHEUR | O11: ACQUET | P11: ACCUSE | Q11: ACTEURS | R11: AGREABLE | S11: AGENCEMENT | T11: ACCONAGE
A12: ACTIONNAIR | B12: ACCLIMATAT | C12: ADWARE | D12: ADHERENT | E12: ADONNER | F12: ACTE | G12: ACCORE | H12: AGIR | I12: ADVERSAIRE | J12: ACCOMMODER | K12: AFFIN | L12: ACRYLIQUE | M12: ADROIT | N12: ACCUEIL | O12: ACQUISE | P12: ACCUSER | Q12: ACTION | R12: AGREMENT | S12: AGGLOMERAT | T12: ACCORE
A13: ACTIVITE | B13: ACCORDER | C13: AFFECTER | D13: ADJACENT | E13: ADOS | F13: ACTEUR | G13: ACCOSTAGE | H13: AGNEAU | I13: AERIEN | J13: ACCORD | K13: AFFINITE | L13: ACTIF | M13: AFFAIRES | N13: ACCUEILLIR | O13: ACQUIT | P13: ACQUERIR | Q13: ACTUALISME | R13: AIR | S13: AGGLOMERE | T13: ACCOSTAGE
A14: ADAPTATEUR | B14: AGE | C14: AFFECTUEUX | D14: ADJOINT | E14: AERER | F14: ACTIVITES | G14: ACCOSTER | H14: AGRESSIF | I14: AERODROME | J14: ACCUEIL | K14: AGE | L14: ACTINIUM | M14: AFFIRME | N14: ACETABULE | O14: ACTIF | P14: ACQUET | Q14: ACTUALITE | R14: ALBUM | S14: AGORA | T14: ACCOSTER
A15: ADAPTATIVE | B15: AGILITE | C15: AFFICHAGE | D15: AFFECTER | E15: AFFINER | F15: ACTRICE | G15: ACONIER | H15: AGRESSIVIT | I15: AERONEF | J15: ACCUSE | K15: AIEUL | L15: ACTINOTE | M15: AFRIQUE | N15: ACINI | O15: ACTION | P15: ACQUIT | Q15: ADAPTATIO | R15: ALLER | S15: AGRANDISSE | T15: ACONIER
A16: ADDICTIF | B16: AGITATION | C16: AFFICHE | D16: AFFINE | E16: AGATIS | F16: ACTUALITE | G16: ACTUAIRE | H16: AGRESTE | I16: AFFAIRE | J16: ACHEMINER | K16: AIEULE | L16: ACTION | M16: AGENTDIPL | N16: ACNE | O16: ACTIVITE | P16: ACQUITTE | Q16: ADMIRATEU | R16: ALPIN | S16: AIR | T16: ACTUAIRE
A17: ADOPTER | B17: AIR | C17: AFFICHEUR | D17: AFFIXE | E17: AGNEAU | F17: ADAGIO | G17: AERIEN | H17: AIGLE | I17: AFFRONTEME | J17: ACOMPTE | K17: AIMANTE | L17: ACTIVATION | M17: AGRICOLE | N17: ACOUSIE | O17: AERIEN | P17: ACTE | Q17: AFFECTE | R17: ALPINISME | S17: ALEM | T17: AERIEN
A18: ADVERSAIRE | B18: ALERTE | C18: AFFILIE | D18: AGREGATION | E18: AGRAIRE | F18: ADMIRATEU | G18: AEROBUS | H18: AIGRETTE | I18: AFFRONTER | J18: ACQUET | K18: AIMER | L18: ACTIVITE | M18: ALBANIE | N18: ACUPUNCTUR | O18: AFFAIRE | P18: ACTIF | Q18: AFFECTIF | R18: AMBULANT | S18: ALFIZ | T18: AEROBUS
A19: ADVERSE | B19: ALIZE | C19: AFFILIER | D19: AIGU | E19: AGRI | F19: ADMIRATION | G19: AERODYNE | H19: AILE | I19: AFFUT | J19: ACQUIT | K19: AINE | L19: ADAMANTIN | M19: ALGER | N19: ADAPTATIF | O19: AFFLUX | P19: ACTION | Q19: AFFECTUEU | R19: AMI | S19: ALLEE | T19: AERODYNE
A20: AERIEN | B20: ALMANACH | C20: AGENT | D20: AIRE | E20: AGRIAL | F20: ADMIRER | G20: AERONAVAL | H20: AIR | I20: AGHA | J20: ACRONYME | K20: AINOU | L20: ADAMITE | M20: ALGERIE | N20: ADAPTEE | O20: AGENCE | P20: ACTIONNER | Q20: AFFICHE | R20: AMIE | S20: AMENAGER | T20: AERONAVAL
A21: AEROBIC | B21: ALTITUDE | C21: AGILE | D21: AJOUT | E21: AGRICOLE | F21: ADRESSE | G21: AERONEF | H21: AIRELLE | I21: AGRESSIF | J21: ACTE | K21: AISEE | L21: ADROIT | M21: ALLEGEANC | N21: ADDUCTEUR | O21: AGENT | P21: ADJUGER | Q21: AIMANT | R21: AMIS | S21: AMEUBLEME | T21: AERONEF
A22: AFFICHAGE | B22: AMBIANCE | C22: AIGUILLE | D22: ALEATOIRE | E22: AGRICULTEU | F22: AEROBIC | G22: AEROPLANE | H22: AJONC | I22: AGRESSION | J22: ACTES | K22: ALLIANCE | L22: ADULAIRE | M22: ALLEMAGNE | N22: ADMINISTRE | O22: AGIO | P22: ADMINISTRA | Q22: AIR | R22: AMITIE | S22: ANARCHIQUE | T22: AEROPLANE
A23: AGILITE | B23: AMPLITUDE | C23: ALARME | D23: ALGEBRE | F23: AEROGRAPHE | G23: AEROSTAT | H23: ALBATROS | I23: AGUERRIR | J23: ACTION | K23: ALLIE | L23: AEGYRINE | M23: ALLIANCE | N23: ADNEE | O23: AGIOTAGE | P23: AFFAIRE | Q23: ALARMANT | R23: ANIMATION | S23: ANNEXION | T23: AEROSTAT
A24: AIKIDO | B24: AMURE | C24: ALEATOIRE | D24: ALGEBRIQUE | E24: AGROLOGIE | F24: AFFICHE | G24: AFFALER | H24: ALBINOS | I24: AIR | J24: ACTIVITE | K24: ALLOCATAIR | L24: AEROSOL | M24: ALOFI | N24: ADOUCIR | O24: AGNEL | P24: AFFERENT | Q24: ALEXANDRIN | R24: AOUTIEN | S24: APPARTEME | T24: AFFALER
A25: AILIER | B25: ANCIENNETE | C25: ALERTE | D25: ALGORITHME | E25: AGRONOME | F25: AGON | G25: AFFINER | H25: ALBUMINE | I25: ALLIANCE | J25: ACTUAIRE | K25: ALLOCATION | L25: AETITE | M25: AMBASSADE | N25: ADRENALINE | O25: AGREAGE | P25: AFFIDAVIT | Q25: ALLEGORIE | R25: ARCHIPEL | S25: AQUEDUC | T25: AFFINER
A26: ALEATOIRE | B26: ANEMOMETRE | C26: ALGEBRE | D26: ALIQUOTE | E26: AGRONOMIE | F26: AIKIDO | G26: AFFRETER | H26: ALEVINS | I26: ALLIE | J26: ADAPTEE | K26: AMI | L26: AFFINITE | M26: AMBASSADEU | N26: AFFECT | O26: AGREEUR | P26: AGNAT | Q26: ALLEGORIQ | R26: ARRET | S26: ARC | T26: AFFRETER
A27: ALLIANCE | B27: ANNEE | C27: ALGORITHME | D27: AMPERE | E27: AGRUME | F27: AIR | G27: AFFRETEUR | H27: ALGOIDE | I27: AMIRAL | J27: ADHESION | K27: AMICAL | L27: AGATE | M27: AMERIQUE | N27: AFFECTER | O27: AGRICOLE | P27: AGREMENT | R27: ARRIVE | S27: ARCADE | T27: AFFRETEUR
A28: ALLIE | B28: ANNUEL | C28: ALIGNEMENT | D28: AMPLITUDE | E28: AIGREUR | F28: AISANCE | G28: AGREEUR | H28: ALGUE | I28: AMIRAUTE | J28: ADJOINT | K28: AMIE | L28: AGILE | M28: AMMAN | N28: AFFECTION | O28: AGUICHE | P28: AIGAGE | Q28: AMPHITHEAT | R28: ARRIVEE | S28: ARCATURE | T28: AGREEUR
A29: ALPINISME | B29: ANTARCTIQU | C29: ALLOCATION | D29: ANALYSE | E29: AIL | F29: ALBUM | G29: AGRES | H29: ALIMENT | I29: AMORCE | J29: ADMINISTRA | K29: AMITIE | L29: AGILITE | M29: AMSTERDAM | N29: AGIR | O29: AIDE | P29: ALIBI | Q29: AMPOULE | R29: ARRIVER | S29: ARCEAU | T29: AGRES
A30: ALUETTE | B30: ANTECEDENT | C30: ALLUMAGE | D30: ANALYSTE | E30: AIMER | F30: ALCHIMIE | G30: AIGUILLEUR | H30: ALIMENTAIR | I30: ANCIEN | K30: AMOUR | L30: AGROALIMEN | M30: ANCIENNE | N30: AGREGE | O30: AISANCE | P30: ALINEA | Q30: ANALEPSE | R30: ART | S30: ARCHEVECH | T30: AIGUILLEUR
A31: AMATEUR | B31: ANTERIORIT | C31: ALLUMER | D31: ANALYTIQUE | E31: AIREE | F31: ALLEGORIE | G31: AIRE | H31: ALLEE | I31: ANIMOSITE | J31: ADMINISTRE | K31: AMOUREUX | L31: AIMANT | M31: ANDORRE | N31: AIDE | O31: ALENA | P31: ALLEGORIE | Q31: ANAPHORE | R31: ARTISANAT | S31: ARCHITECTE | T31: AIRE
A32: AMBIANCE | B32: ANTICYCLON | C32: ALPHA | D32: ANGLE | E32: ALEVINAGE | F32: ALLEGRO | G32: AJUT | H32: ALLIGATOR | I32: ANNEXION | J32: ADOPTION | K32: ANALOGIE | L32: AIR | M32: ANGLAIS | N32: AIDER | O32: ALLOCATION | P32: ALLEGUER | Q32: ANGELISME | R32: ATOUT | T32: AJUT
A33: AMICAL | B33: ANTIQUITE | C33: AMER | D33: ANNEAU | E33: ALFA | F33: ALTO | G33: ALBATROS | H33: ALPAGA | J33: ADRESSE | K33: ANCESTRAL | L33: AIRAIN | M33: ANGLETERRE | N33: AIGUILLE | O33: ALOI | P33: ALLOTER | Q33: ANONYME | R33: ATTIRE | S33: ARCOLOGIE | T33: ALBATROS
A34: AMORTI | B34: ARBRE | C34: AMERTUME | D34: ANSE | E34: ALFATIER | F34: AMATEUR | G34: ALERTE | H34: ALPIN | I34: ANTAGONIST | J34: AFFAIRE | K34: ANCETRE | L34: AIRE | M34: ANGOLA | N34: AILE | O34: ALTERATION | P34: AMENDE | Q34: ANTHOLOGIE | R34: ATTRACTIF | S34: AREA | T34: ALERTE
A35: AMPHITHEAT | B35: ARC | C35: AMITIE | D35: ANTECEDENT | E35: ALIMENT | F35: AMBITION | G35: ALGUES | H35: ALPINE | I35: ANTICHAR | J35: AGENCE | K35: ANTECEDENT | L35: ALABANDINE | M35: ANKARA | N35: AINE | O35: AMENDE | P35: AMIABLE | Q35: ANTITHESE | R35: ATTRACTION | S35: ART | T35: ALGUE
A36: AMUSANT | B36: ARCENCIEL | C36: AMNESIE | D36: ANTINOMIE | E36: ALPAGE | F36: ANDANTE | G36: ALLEE | H36: ALTRUISTE | I36: ANTIDROGUE | J36: AGENCEMENT | K36: ANTHROPOLO | L36: ALABANDITE | M36: ANNEXER | N36: AIR | O36: AMENDER | P36: AMISSION | Q36: APARTES | R36: ATTRAIT | S36: ARTERE | T36: ALGUES
A37: AMUSEMENT | B37: ARCTIQUE | C37: AMORCE | D37: APOTHEME | E37: AMELIORER | F37: ANIMATEUR | G37: ALLEGE | H37: AMERINDIEN | J37: AGENCER | K37: APPARENTE | L37: ALBATRE | M37: ANNEXION | N37: AISSELLE | O37: AMITIE | P37: ANNAL | Q37: APHORISME | R37: AUBERGE | S37: ARTIFICIAL | T37: ALLEE
A38: AMUSER | B38: ARIDE | C38: AMOVIBLE | D38: APPLICATIO | E38: AMENAGER | F38: ANTILABE | G38: ALLERVOILE | H38: AMIBE | I38: ANTITABAC | J38: AGENT | K38: APPARENTEM | L38: ALBEDO | M38: APIA | N38: AJUSTER | O38: AMORTIR | P38: ANNALE | Q38: APOLOGUE | R38: AUTOCAR | S38: ARTISTE | T38: ALLEGE
A39: ANALYSER | B39: ARIDITE | C39: AMPLIFIER | D39: APPLIQUER | E39: AMENDEMENT | F39: ANTIQUE | G39: ALLURE | H39: AMPHIBIE | I39: ANTITERROR | J39: AGORA | K39: APPARTEMEN | L39: ALBITE | M39: APPEL | N39: ALCALOIDE | O39: AMPLEUR | P39: ANNEXE | Q39: APOSTROPHE | R39: AUTORAIL | S39: ASPECT | T39: ALLERVOILE
A40: ANIMATEUR | B40: ARROSAGE | C40: AMULETTE | D40: APPROXIMER | E40: AMEUBLIR | F40: ANTIQUITE | G40: ALOSE | H40: ANATOMIE | I40: APOTRE | J40: AGREE | K40: APPARTENAN | L40: ALBUGINE | M40: ARABIE | N40: ALIENE | O40: ANALYSE | P40: ANNULATION | Q40: APPRETE | R40: AVENTURE | S40: ASPHALTE | T40: ALLURE
...

Sheet M4
A1: ALKAMO — M4
A2: N° | B2: THÈME | C2: MOTS
A3: 1 | B3: CONCEPT ET IDÉE | C3: =COUNTA(M4_mots!A3:A5000) -> 407
A4: 2 | B4: ÉMOTION | C4: =COUNTA(M4_mots!B3:B5000) -> 446
A5: 3 | B5: COULEUR | C5: =COUNTA(M4_mots!C3:C5000) -> 453
A6: 4 | B6: PHYSIQUE | C6: =COUNTA(M4_mots!D3:D5000) -> 671
A7: 5 | B7: CUISINE ET GASTRO | C7: =COUNTA(M4_mots!E3:E5000) -> 763
A8: 6 | B8: CORPS HUMAIN | C8: =COUNTA(M4_mots!F3:F5000) -> 929
A9: 7 | B9: CULTURE | C9: =COUNTA(M4_mots!G3:G5000) -> 297
A10: 8 | B10: ARCHÉOLOGIE | C10: =COUNTA(M4_mots!H3:H5000) -> 609
A11: 9 | B11: INSECTE ET REPTILE | C11: =COUNTA(M4_mots!I3:I5000) -> 547
A12: 10 | B12: HISTOIRE | C12: =COUNTA(M4_mots!J3:J5000) -> 456
A13: 11 | B13: LITTÉRATURE | C13: =COUNTA(M4_mots!K3:K5000) -> 649
A14: 12 | B14: CÉLÉBRITÉ | C14: =COUNTA(M4_mots!L3:L5000) -> 492
A15: 13 | B15: BRAVOURE | C15: =COUNTA(M4_mots!M3:M5000) -> 386
A16: 14 | B16: TECHNOLOGIE | C16: =COUNTA(M4_mots!N3:N5000) -> 1100
A17: 15 | B17: MÉTÉO ET CLIMAT | C17: =COUNTA(M4_mots!O3:O5000) -> 571
A18: 16 | B18: ARCHITECTURE | C18: =COUNTA(M4_mots!P3:P5000) -> 1512
A19: 17 | B19: DÉCORATION | C19: =COUNTA(M4_mots!Q3:Q5000) -> 585
A20: 18 | B20: MONTAGNE ET DÉSERT | C20: =COUNTA(M4_mots!R3:R5000) -> 503
A21: 19 | B21: POISSON ET MER | C21: =COUNTA(M4_mots!S3:S5000) -> 1266
A22: 20 | B22: MARKETING | C22: =COUNTA(M4_mots!T3:T5000) -> 205
A23: TOTAL | C23: =SUM(C3:C22) -> 12847

Sheet M4_mots
A1: CONCEPT ET IDÉE | B1: ÉMOTION | C1: COULEUR | D1: PHYSIQUE | E1: CUISINE ET GASTRO | F1: CORPS HUMAIN | G1: CULTURE | H1: ARCHÉOLOGIE | I1: INSECTE ET REPTILE | J1: HISTOIRE | K1: LITTÉRATURE | L1: CÉLÉBRITÉ | M1: BRAVOURE | N1: TECHNOLOGIE | O1: MÉTÉO ET CLIMAT | P1: ARCHITECTURE | Q1: DÉCORATION | R1: MONTAGNE ET DÉSERT | S1: POISSON ET MER | T1: MARKETING
A2: =COUNTA(A3:A5000) -> 407 | B2: =COUNTA(B3:B5000) -> 446 | C2: =COUNTA(C3:C5000) -> 453 | D2: =COUNTA(D3:D5000) -> 671 | E2: =COUNTA(E3:E5000) -> 763 | F2: =COUNTA(F3:F5000) -> 929 | G2: =COUNTA(G3:G5000) -> 297 | H2: =COUNTA(H3:H5000) -> 609 | ... T2: =COUNTA(T3:T5000) -> 205
A3: ABSTRAIT | B3: ABANDON | C3: ABONDANCE | D3: ABDOMEN | E3: ABAISSER | F3: ABCES | G3: ABBAYE | H3: ABAQUE | I3: ABDOMEN | J3: ABOLIR | K3: ABSTRACTIO | L3: ABONNES | M3: ABIME | N3: ABRASIF | O3: ABAT | P3: ABAQUE | Q3: ABATJOUR | R3: ABIME | S3: ABER | T3: ACCAPARER
A4: ABSTRAITE | B4: ABATTU | C4: ABRICOT | D4: ACOUSTIQUE | E4: ABATS | F4: ABDOMEN | G4: ABSTRAIT | H4: ABRI | I4: ABDOMINAL | J4: ABOLITION | K4: ABSTRAIT | L4: ACCLAMER | M4: ABNEGATION | N4: ABRASION | O4: ABIME | P4: ABAT | Q4: ACAJOU | R4: ABORDER | S4: ABIME | T4: ACCROCHE
A5: ACCEPTION | B5: ABSENCE | C5: ABSINTHE | D5: ACTIF | E5: ABONDANCE | F5: ABDOS | G5: ACADÉMIE | H5: ABSIDE | I5: ABEILLE | J5: ABREGE | K5: ACADEMICIE | L5: ACCOMPLI | M5: ACIER | N5: ABSORBEUR | O5: ABRI | P5: ABATTRE | Q5: ACCROCHE | R5: ABRI | S5: ABLE | T5: ACHAT
A6: ACCORD | B6: ABSURDE | C6: ACAJOU | D6: ACTION | E6: ABONDANT | F6: ABDUCT | G6: ACCORD | H6: ACANTHUS | I6: ABRAXAS | J6: ABROGATION | K6: ACADEMISME | L6: ACTEUR | M6: ACTIF | N6: ACCES | O6: ACCALMIE | P6: ABBAYE | Q6: ACCROCHER | R6: ABRITER | S6: ABLETTE | T6: ACHETEUR
A7: ACTE | B7: ACCABLÉ | C7: ACCORD | D7: ACTIVITE | E7: ABOUTI | F7: ABSORBER | G7: ADOPTION | H7: ACCES | I7: ACARIEN | J7: ACADEMIE | K7: ACCENT | L7: ACTIF | M7: ACTIVE | N7: ACCUMULER | O7: ACRE | P7: ABOUTIR | Q7: ACIER | R7: ABRUPT | S7: ABONDANCE | T7: ACQUÉRIR
A8: ACTUEL | B8: ACCEPTER | C8: ACIER | D8: ADROIT | E8: ABRICOT | F8: ACNE | G8: AFFINITÉ | H8: ACHEULIEN | I8: ACAROLOGIE | J8: ACCESSION | K8: ACCESSOIRE | L8: ACTRICE | M8: ADMIRABLE | N8: ACIDE | O8: ACTUEL | P8: ABREUVOIR | Q8: ADOUCIR | R8: ABYSSAL | S8: ABORD | T8: ACTIVITÉ
A9: ADAPTATION | B9: ADMIRER | C9: AGRESSIVE | D9: AFFINITE | E9: ABSINTHE | F9: ACUITE | G9: AGRUME | H9: ACIER | I9: ACRIDIEN | J9: ACIER | K9: ACROSTICHE | L9: ADHESION | M9: AFFRANCHIR | N9: ACIER | O9: AERIEN | P9: ABRI | Q9: AERIEN | R9: ACACIA | S9: ABORDAGE | T9: ADHÉRENT
A10: AFFIRMER | B10: ADORER | C10: AIGUE | D10: AGILE | E10: ACCOMPLI | F10: ADIPE | G10: AMBIANCE | H10: ACROPOLE | I10: ACROLOGIE | J10: ACROPOLE | K10: ACTE | L10: ADMIRABLE | M10: AFFRONTER | N10: ACTIF | O10: AGIR | P10: ABSIDE | Q10: AFFICHER | R10: ACACIAS | S10: ABORDER | T10: ADOPTION
A11: ALGEBRE | B11: AFFECT | C11: ALBATRE | D11: AGILITE | E11: ACCORD | F11: ADN | G11: APPORT | H11: ADOBE | I11: ACRONICTE | J11: ADHESION | K11: ACTEURS | L11: ADMIRATEUR | M11: AGILE | N11: ACTIVER | O11: AGITE | P11: ABSTRAIT | Q11: AGENCER | R11: ACCLIVE | S11: ABYME | T11: AFFAIRE
A12: ALLEGORIE | B12: AFFECTER | C12: ALERTE | D12: AIR | E12: ACCUEIL | F12: ADOLESCENT | G12: ARABLE | H12: AFFINAGE | I12: ADALIA | J12: AGORA | K12: ACTION | L12: ADMIRATION | M12: AGIR | N12: ADAPTATEUR | O12: AGREABLE | P12: ACAJOU | Q12: AGREMENTER | R12: ACIER | S12: ABYSSAL | T12: AFFICHAGE
A13: AMBITION | B13: AFFECTIF | C13: ALEZAN | D13: AIRE | E13: ACCUEILLI | F13: ADRENALINE | G13: ARCHIVES | H13: AFFOUILLER | I13: ADULTE | J13: AGREGATION | K13: ACTUALISME | L13: ADMIRER | M13: AGUERRI | N13: ADHERENCE | O13: AIR | P13: ACANTHUS | Q13: AJOURE | R13: ACRE | S13: ABYSSE | T13: AFFICHE
A14: ANALOGIE | B14: AFFLICTION | C14: AMARANTE | D14: ALBEDO | E14: ACETO | F14: ADRESSE | G14: ART | H14: AGGLOMERE | I14: AESHNE | J14: AGRESSION | K14: ACTUALITE | L14: ADORER | M14: AIDER | N14: AFFAIBLIR | O14: ALBEDO | P14: ACCES | Q14: AJUSTER | R14: ADDAX | S14: ACANTHURE | T14: AGENCE
... A26: ARGUMENTER | B26: AMERTUME | C26: ARDENT | D26: ANDROGYNE | E26: AIGRE | F26: ALCOOL | G26: BILDUNG | H26: AMMONITE | I26: AIGLE | J26: ANGE | K26: ALLEGORIQ | L26: ALIAS | M26: ARDEUR | N26: ALESAGE | O26: ANNEE | P26: ACTUEL | Q26: ANTIQUE | R26: ALPIN | S26: ACTIF | T26: ATTRACTIF
A27: ART | B27: AMITIÉ | C27: ARDEUR | D27: ANGLE | E27: AIGUILLAT | F27: ALERTE | G27: BLUES | H27: AMPHORE | I27: AIGUILLON | J27: ANIMATION | L27: ALLEGRESSE | M27: ARME | N27: ALESOIR | O27: ANTRE | P27: ADAMANTIN | Q27: APPLIQUE | R27: ALPINISME | S27: ACTINIE | T27: BAISSER
A28: ASPECT | B28: AMOUR | C28: ARDOISE | D28: ANIMAL | E28: AIL | F28: ALGIE | G28: BLÉ | H28: AMULETTE | I28: AILE | J28: ANNALE | K28: AMPHITHEAT | L28: ALLURE | M28: ARMEE | N28: ALGEBRE | O28: APEX | P28: ADAPTER | Q28: ARABESQUE | R28: ALPINISTE | S28: ACTIVE | T28: BONIMENT
A29: ASPIRER | B29: AMOUREUX | C29: ARGENT | D29: ANIMALES | E29: AILE | F29: ALITER | G29: BRÛLIS | H29: ANALYSER | I29: AIR | J29: ANNALES | K29: AMPOULE | L29: AMBITIEUX | M29: ARMURE | N29: ALGORITHME | O29: APRE | P29: ADENT | Q29: ARCADE | R29: ALTIPLANO | S29: ACUL | T29: BOUTIQUE
A30: ASSIMILE | B30: AMYGDALE | C30: ARGENTE | D30: ANIMER | E30: AIOLI | F30: ALLERGIE | G30: BÉTAIL | H30: ANCRAGE | I30: ALGUE | J30: ANNEXION | K30: ANALEPSE | L30: AMBITION | M30: ARTILLERIE | N30: ALIGNEMENT | O30: AQUA | P30: ADEQUATION | Q30: ARDOISE | R30: ALTITUDE | S30: ADENT | T30: BRANCHE
A31: ATYPIQUE | B31: AMÉNITÉ | C31: ARGENTER | D31: ANNULAIRE | E31: AIR | F31: ALLURE | G31: CABARET | H31: ANNEAU | I31: ALLIGATOR | J31: ANTIQUE | K31: ANAPHORE | L31: AMI | M31: ASSAUT | N31: ALIGNER | O31: AQUEUX | P31: ADOBE | Q31: ARETE | R31: AMAS | S31: ADHERENCE | T31: BROCHURE
A32: AXIOME | B32: ANGOISSE | C32: ARGENTIN | E32: AIRELLE | F32: ALVEOLE | G32: CAFÉIER | H32: ANTIQUE | I32: ALLOPHES | J32: ANTIQUITE | K32: ANGELISME | L32: AMOUR | M32: ASSURANCE | N32: ALIMENTER | O32: ARBRE | P32: ADOSSEMENT | Q32: ARGENT | R32: ANCRE | S32: ADJOINT | T32: BRUT
A33: BASE | B33: ANTIPATHIE | C33: ART | D33: APPARENCE | E33: AJOUTER | F33: AMAIGRIRE | G33: CAMPAGNE | H33: ANTIQUITE | I33: ALVEOLE | J33: APOCRYPHE | K33: ANONYME | L33: ANIMATEUR | M33: ATTAQUE | N33: ALLIAGE | O33: ARC | P33: ADRESSE | Q33: ARGILE | R33: ANGLE | S33: ADOS | T33: BULLETIN
A34: BEAU | B34: ANXIEUX | C34: ARTIFICIEL | D34: APPDIGEST | E34: ALGUE | F34: AMBITION | G34: CAPITAL | H34: AQUEDUC | I34: ALYTE | J34: ARBITRAGE | K34: ANTHOLOGIE | L34: ANIMATION | M34: AUBE | N34: ALLOCATION | O34: ARCEN | P34: AFFLEUR | Q34: ARMATURE | R34: ARBRE | S34: ADRET | T34: CADEAU
A35: BIAIS | B35: ANXIÉTÉ | C35: ARTISTE | D35: APPOINT | E35: ALLIAGE | F35: AME | G35: CARNAVAL | H35: ARASE | I35: AMPEDUS | J35: ARC | K35: ANTITHESE | L35: ANNONCE | M35: AUDACE | N35: ALLONGE | O35: ARCHIPEL | P35: AFFLEURER | Q35: ARMOIRE | R35: ARCHE | S35: AFALE | T35: CAMPAGNE
A36: BIEN | B36: APAISER | C36: ASSORTIR | D36: APTE | E36: ALLIE | F36: AMYGDALE | G36: CENSURE | H36: ARASER | I36: AMPHIBIEN | J36: ARCHAISME | K36: APARTES | L36: ANONYMAT | M36: AUDACIEUX | N36: ALLUMER | O36: ARCTIQUE | P36: AGATE | Q36: ASSEMBLER | R36: ARDEUR | S36: AFFALER | T36: CASSER
A37: BIOLOGIE | B37: APAISÉ | C37: AUBERGINE | D37: APTITUDE | E37: ALOSE | F37: ANALYSE | G37: CERCLE | H37: ARCADE | I37: AMPHIBOL | J37: ARCHIVE | K37: APHORISME | L37: APOGEE | M37: AVANCEE | N37: AMORCER | O37: ARENE | P37: AGENCEMENT | Q37: ASSISE | R37: ARDOISE | S37: AFFE | T37: CATALOGUE
A38: BIOLOGIQUE | B38: APATHIE | C38: AUDACE | E38: AMANDE | F38: ANEMIE | G38: CHAMP | H38: ARCHE | I38: ANACONDA | J38: ARCHIVER | K38: APOLOGUE | L38: APPARAT | M38: AVANCER | N38: AMPLIFIER | O38: ARGENT | P38: AGENCER | Q38: ASSORTIR | R38: ARENE | S38: AFFET | T38: CHAMPION
A39: BLAME | B39: APEURÉ | C39: AURORE | D39: ARISTOTE | E39: AMER | F39: ANGINE | G39: CHANSON | H39: ARCHIVE | I39: ANAX | J39: ARCHIVES | K39: APOSTROPHE | L39: APPARENCE | M39: BADGE | N39: AMPOULE | O39: ARGILE | P39: AGENT | Q39: ATRIUM | R39: ARETE | S39: AFFIN | T39: CHOQUANT
A40: BONHEUR | B40: APITOYER | C40: AVIVER | D40: ASPECT | E40: AMPLEUR | F40: ANGOISSE | G40: CHANVRE | H40: ARCHIVER | I40: ANDRENE | J40: ARGENT | K40: APPRETE | L40: APPLAUDI | M40: BAIONNETTE | N40: ANALOGIQUE | O40: ARIDE | P40: AGGLOMERE | Q40: ATTIRER | R40: ARGILE | S40: AFFOURCHER | T40: CIBLAGE
A41: BUT | B41: APPÉTIT | C41: AZUR | D41: ASTHENIE | E41: AMUSE | F41: ANOSMIE | G41: CHEF | H41: ARDOISE | I41: ANGUIS | J41: ARMEE | K41: ARABE | L41: APPLAUDIR | M41: BASTION | N41: ANALYSE | O41: ARIDITE | P41: AGGLOMERER | Q41: ATTRAIT | R41: ARIDE | S41: AFFRET | T41: CIBLE
A42: CADRE | B42: ARDENT | C42: AZURE | E42: ANCHOIS | F42: ANUS | G42: CHÂTEAU | H42: ARENE | I42: ANIMAL | J42: ARMISTICE | K42: ARGUMENT | L42: APPRECIER | M42: BATAILLE | N42: ANALYSER | O42: ARME | P42: AGILE | Q42: AUVENT | R42: AROLE | S42: AFFRETEUR | T42: CIBLER
A43: CAS | B43: ARDEUR | C43: AZUREE | D43: ATHLETE | E43: ANDOUILLE | F43: AORTE | G43: CINÉMA | H43: ARGENT | I43: ANISOPLIE | J43: ART | K43: ARIA | L43: APPUI | M43: BATAILLON | N43: ANCRAGE | O43: ARRET | P43: AGORA | Q43: AZUR | R43: ASPERITE | S43: AFFUT | T43: CLIENT
A44: CATEGORIE | B44: ARTISTE | C44: BASALTE | D44: ATOME | E44: ANETH | F44: APEX | G44: CIRQUE | H44: ARGILE | I44: ANNEAU | J44: ARTICLE | K44: ARRANGE | L44: APPUYER | M44: BIVOUAC | N44: ANCRER | O44: ARROSER | P44: AGRAFAGE | Q44: BADIGEON | R44: ASPRE | S44: AGENCE | T44: CLIENTÈLE
A45: CAUSALITE | B45: ASPIRER | C45: BEIGE | D45: ATOMIQUE | E45: ANGULE | F45: APHASIE | G45: CIVILISÉ | H45: ARKOSE | I45: ANOPHELE | J45: ARTISTIQUE | K45: ART | L45: ARDEUR | M45: BOMBE | N45: ANGLE | O45: ASPRE | P45: AGRAFE | Q45: BAGUETTE | R45: ATTEINDRE | S45: AGENT | T45: CLIGNOTER
A46: CAUSE | B46: ATARAXIE | C46: BICOLORE | D46: ATOMISME | E46: ANIS | F46: APNEE | G46: CIVISME | H46: ARME | I46: ANTENNE | J46: ASCENSION | K46: ARTHURIEN | L46: ARGENT | M46: BONTE | N46: ANGULAIRE | O46: ASTRE | P46: AGRAFFAGE | Q46: BAHUT | R46: AVALANCHE | S46: AGITE | T46: CLIP
A47: CERNER | B47: ATTITUDE | C47: BICROMATE | E47: APERITIF | F47: APPENDICE | G47: CLEF | H47: ARMER | I47: AOUTAT | J47: ASSASSINAT | K47: ARTIFICIE | L47: ARROGANCE | M47: BOUCLIER | N47: ANNOTATION | O47: ATMOSPHERE | P47: AGRANDIR | Q47: BALCON | R47: AVANCER | S47: AGITEE | T47: COMMERCE
A48: CERTITUDE | B48: ATTRISTÉ | C48: BISTRE | D48: AUTORITE | E48: APOGEE | F48: ARCEAU | G48: CLIMAT | H48: ARSENIC | I48: APAMEE | J48: ASSEMBLEE | K48: ARTISTE | L48: ARTICLE | M48: BRASIER | N48: ANNULER | O48: AUBE | P48: AGREE | Q48: BALDAQUIN | R48: AVENTURE | S48: AGREMENT | T48: COMMERCER
A49: CHAMP | B49: AVARICE | C49: BITUME | D49: BACON | E49: APPETIT | F49: ARCHE | G49: CODE | H49: ARTEFACT | I49: APATURA | J49: AURELE | K49: ARTISTIQUE | L49: ARTISTE | M49: BRAVADE | N49: ANODE | O49: AURORE | P49: AIGUILLE | Q49: BAMBOU | R49: BARCANE | S49: AGRES | T49: COÛT
A50: CHIMIE | B50: AVERSION | C50: BLANC | D50: BALEZE | E50: APPRECIER | F50: ARCHET | G50: COHÉSION | H50: ARTISAN | I50: APHELIE | J50: AUTEUR | K50: ASPECT | L50: ASCENSION | M50: BRAVE | N50: ANTENNE | O50: AUSTRAL | P50: AILE | Q50: BANDE | R50: BARRE | S50: AGUER | T50: CRÉATIF
A51: CHOIX | B51: AVIDITÉ | C51: BLANCHIR | D51: BARAQUE | E51: ARACHIDE | F51: ARDEUR | G51: COLON | H51: ASSEMBLAGE | I51: APHODIUS | J51: AUTORITE | K51: ASSONANCE | L51: ATOUT | M51: BRAVER | N51: ANTIVIRUS | O51: AUTOMNE | P51: AILERON | Q51: BANDEAU | R51: BASALTE | S51: AHURI | T51: CRÉER
...

Sheet M5
A1: ALKAMO — M5
A2: N° | B2: THÈME | C2: MOTS
A3: 1 | B3: ARCHITECTURE | C3: =COUNTA(M5_mots!A3:A5000) -> 1512
A4: 2 | B4: ART | C4: =COUNTA(M5_mots!B3:B5000) -> 971
A5: 3 | B5: HISTOIRE | C5: =COUNTA(M5_mots!C3:C5000) -> 456
A6: 4 | B6: ASTRONOMIE | C6: =COUNTA(M5_mots!D3:D5000) -> 601
A7: 5 | B7: MÉDECINE | C7: =COUNTA(M5_mots!E3:E5000) -> 809
A8: 6 | B8: COMMUNICATION | C8: =COUNTA(M5_mots!F3:F5000) -> 551
A9: 7 | B9: THÉÂTRE | C9: =COUNTA(M5_mots!G3:G5000) -> 405
A10: 8 | B10: ÉCONOMIE | C10: =COUNTA(M5_mots!H3:H5000) -> 638
A11: 9 | B11: DROIT | C11: =COUNTA(M5_mots!I3:I5000) -> 706
A12: 10 | B12: RELIGION | C12: =COUNTA(M5_mots!J3:J5000) -> 632
A13: 11 | B13: CONCEPT ET IDÉE | C13: =COUNTA(M5_mots!K3:K5000) -> 407
A14: 12 | B14: INDUSTRIE | C14: =COUNTA(M5_mots!L3:L5000) -> 659
A15: 13 | B15: HUMANITÉ | C15: =COUNTA(M5_mots!M3:M5000) -> 715
A16: 14 | B16: TOURISME | C16: =COUNTA(M5_mots!N3:N5000) -> 367
A17: 15 | B17: CULINAIRE | C17: =COUNTA(M5_mots!O3:O5000) -> 839
A18: 16 | B18: NAVIGATION | C18: =COUNTA(M5_mots!P3:P5000) -> 1093
A19: 17 | B19: LITTÉRATURE | C19: =COUNTA(M5_mots!Q3:Q5000) -> 649
A20: 18 | B20: COMMERCE | C20: =COUNTA(M5_mots!R3:R5000) -> 1019
A21: 19 | B21: SPORT | C21: =COUNTA(M5_mots!S3:S5000) -> 579
A22: 20 | B22: URBANISME | C22: =COUNTA(M5_mots!T3:T5000) -> 628
A23: 21 | B23: MILITAIRE | C23: =COUNTA(M5_mots!U3:U5000) -> 774
A24: 22 | B24: ÉNERGIE | C24: =COUNTA(M5_mots!V3:V5000) -> 754
A25: 23 | B25: AGRONOMIE | C25: =COUNTA(M5_mots!W3:W5000) -> 848
A26: 24 | B26: TEXTILE | C26: =COUNTA(M5_mots!X3:X5000) -> 1458
A27: 25 | B27: DIPLOMATIE | C27: =COUNTA(M5_mots!Y3:Y5000) -> 904
A28: TOTAL | C28: =SUM(C3:C27) -> 18974

Sheet M5_mots
A1: ARCHITECTURE | B1: ART | C1: HISTOIRE | D1: ASTRONOMIE | E1: MÉDECINE | F1: COMMUNICATION | G1: THÉÂTRE | H1: ÉCONOMIE | I1: DROIT | J1: RELIGION | K1: CONCEPT ET IDÉE | L1: INDUSTRIE | M1: HUMANITÉ | N1: TOURISME | O1: CULINAIRE | P1: NAVIGATION | Q1: LITTÉRATURE | R1: COMMERCE | S1: SPORT | T1: URBANISME | U1: MILITAIRE | V1: ÉNERGIE | W1: AGRONOMIE | X1: TEXTILE | Y1: DIPLOMATIE
A2: =COUNTA(A3:A5000) -> 1512 | B2: =COUNTA(B3:B5000) -> 971 | C2: =COUNTA(C3:C5000) -> 456 | D2: =COUNTA(D3:D5000) -> 601 | E2: =COUNTA(E3:E5000) -> 809 | F2: =COUNTA(F3:F5000) -> 551 | G2: =COUNTA(G3:G5000) -> 405 | H2: =COUNTA(H3:H5000) -> 638 | ... Y2: =COUNTA(Y3:Y5000) -> 904
A3: ABAQUE | B3: ABSTRAIT | C3: ABOLIR | D3: ABSIDE | E3: ABCES | F3: ABONNÉ | G3: ABSURDE | H3: ACCUMULER | I3: ABANDON | J3: ABBAYE | K3: ABSTRAIT | L3: ABATTOIR | M3: ABNEGATION | N3: ABRI | O3: ABAISSER | P3: ABATEE | Q3: ABSTRACTIO | R3: ABATAGE | S3: ACROBATIE | T3: ABRI | U3: ABRI | V3: ABATTAGE | W3: ABATTOIR | X3: ABACA | Y3: ABDIQUER
A4: ABAT | B4: ACADEMISME | C4: ABOLITION | D4: ACCOMPLIR | E4: ABDOMEN | F4: ACCENT | G4: ACCESSOIRE | H4: ACHAT | I4: ABATTEMENT | J4: ABBE | K4: ABSTRAITE | L4: ABRASION | M4: ABOUTIR | N4: ACCUEIL | O4: ABATS | P4: ABER | Q4: ABSTRAIT | R4: ACCORD | S4: ACROSPORT | T4: ABRIBUS | U4: ACADEMIE | V4: ABSORPTION | W4: ABATTRE | X4: ABEILLE | Y4: ABITRER
A5: ABATTRE | B5: ACCORD | C5: ABREGE | D5: ACCRETION | E5: ABOLIR | F5: ACCEPTER | G5: ACCLAMER | H5: ACQUISE | I5: ABDIQUER | J5: ABBESSE | K5: ACCEPTION | L5: ACHAT | M5: ABRI | N5: AEROPORT | O5: ABONDANCE | P5: ABORD | Q5: ACADEMICIE | R5: ACCORDER | S5: ACTIF | T5: ABSIDE | U5: ACCORD | V5: ACCELERATE | W5: ABEILLE | X5: ABLATION | Y5: ABOLIR
A6: ABBAYE | B6: ACCORDAGE | C6: ABROGATION | D6: ACRAB | E6: ABSORPTION | F6: ACCLAMER | G6: ACCORD | H6: ACQUIT | I6: ABOLIR | J6: ABJURER | K6: ACCORD | L6: ACIDE | M6: ABRITER | N6: AFFLUENT | O6: ABONDANT | P6: ABORDAGE | Q6: ACADEMISME | R6: ACCUMULER | S6: ACTION | T6: ACCROISSEM | U6: ACHARNE | W6: ABREUVER | X6: ACADEMIE | Y6: ABOLITION
A7: ABOUTIR | B7: ACCORDEON | C7: ACADEMIE | D7: ACTEUR | E7: ACADEMIE | F7: ACCORD | G7: ACCUEIL | H7: ACTIF | I7: ABROGER | J7: ABLUTION | K7: ACTE | L7: ACIER | M7: ABSOUDRE | N7: AFFLUX | O7: ABOUTI | P7: ABORDER | Q7: ACCENT | R7: ACHAT | S7: ACTIVITE | T7: ACCROTERE | U7: ACHARNEMEN | V7: ACCUMULATE | W7: ABREUVOIR | X7: ACCESSOIRE | Y7: ABORDER
A8: ABREUVOIR | B8: ACCORDEUR | C8: ACCESSION | D8: ACTIVITE | E8: ACCOUCHEUR | F8: ACCÈS | G8: ACROBATE | H8: ACTION | I8: ABSOLUTION | J8: ABSIDE | K8: ACTUEL | L8: ACIERIE | M8: ACCEPTER | N8: AGENCE | O8: ABRICOT | P8: ABRI | Q8: ACCESSOIRE | R8: ACHETER | S8: ADVERSAIRE | T8: ACIER | U8: ACHEEN | V8: ACHAT | W8: ABRICOT | X8: ACCLAME | Y8: ABOUTIR
A9: ABRI | B9: ACCROCHE | C9: ACIER | D9: AERODYNE | E9: ACCUEIL | F9: ACRONYME | G9: ACTE | H9: AFFAIRE | I9: ABSOUDRE | J9: ABSOLUTION | K9: ADAPTATION | L9: ACRYLIQUE | M9: ACCOMPLIR | N9: AGREMENT | O9: ABSINTHE | P9: ABYSSAL | Q9: ACROSTICHE | R9: ACHETEUR | S9: AEROBIC | T9: ACROPOLE | U9: ACIER | V9: ACHETER | W9: ABSINTHE | X9: ACCOUCHEME | Y9: ABSENCE
A10: ABSIDE | B10: ACHROME | C10: ACROPOLE | D10: AEROLITE | E10: ACCUEILLIR | F10: ACTE | G10: ACTEUR | H10: AGENCE | I10: ABUS | J10: ABSOUDRE | K10: AFFIRMER | L10: ACTIF | M10: ACCORD | N10: AGRICULTUR | O10: ACCOMPLI | P10: ACCALMIE | Q10: ACTE | R10: ACOMPTE | S10: AIKIDO | T10: AEROPORT | U10: ACTION | V10: ACRETE | W10: ACACIA | X10: ACCROC | Y10: ABSOUDRE
A11: ABSTRAIT | B11: ACORDE | C11: ADHESION | D11: AGIR | E11: ACNE | F11: ADRESSE | G11: ACTION | H11: AGENT | I11: ABUSER | J11: ABSOUTE | K11: ALGEBRE | L11: ACTIVITE | M11: ACCORDER | N11: AGROTOURIS | O11: ACCORD | P11: ACCONAGE | Q11: ACTEURS | R11: ACQUET | S11: AILIER | T11: AGENCEMENT | U11: ACTIVISTE | V11: ACTINIDE | W11: ACAJOU | X11: ACCROCHE | Y11: ABSTENIR
A12: ACAJOU | B12: ACTE | C12: AGORA | D12: AGO | E12: ACOUSIE | F12: ADRESSER | G12: ACTRICE | H12: AGIO | I12: ACCEDER | J12: ABSTENIR | K12: ALLEGORIE | L12: ADAPTATION | M12: ACCUEIL | N12: AIR | O12: ACCUEIL | P12: ACCORE | Q12: ACTION | R12: ACQUISE | S12: ALPINISME | T12: AGGLOMERAT | U12: ADJUDANT | V12: ACTION | W12: ACARIEN | X12: ACETATE | Y12: ACADEMIE
A13: ACANTHUS | B13: ACTEUR | C13: AGREGATION | D13: AIR | E13: ACUPUNCTUR | F13: AFFICHAGE | G13: ADAGIO | H13: AGIOTAGE | I13: ACCESSION | J13: ABSTINENCE | K13: AMBITION | L13: ADDITIF | M13: ACE | N13: ALBUM | O13: ACCUEILLI | P13: ACCOSTAGE | Q13: ACTUALISME | R13: ACQUIT | S13: AMATEUR | T13: AGGLOMERE | U13: ADVERSAIRE | V13: ACTIONNEUR | W13: ACHENE | X13: ACHAT | Y13: ACCEDER
A14: ACCES | B14: ACTIVITES | C14: AGRESSION | D14: AKARNAR | E14: ADMINISTRE | F14: AFFICHE | G14: ADRESSE | H14: AGNEL | I14: ACCORD | J14: ACEDIE | K14: ANALOGIE | L14: ADJUVANT | M14: ACHAT | N14: ALLER | O14: ACETO | P14: ACCOSTER | Q14: ACTUALITE | R14: ACTIF | S14: AMICAL | T14: AGORA | U14: AERIEN | V14: ACTIVITE | W14: ACIDITE | X14: ACRYLIQUE | Y14: ACCEPTER
A15: ACCOLADE | B15: ACTRICE | C15: ALCHIMISTE | D15: ALBEDO | E15: ADOUCIR | F15: AGENCE | G15: AFFICHE | H15: AGRICOLE | I15: ACCUEILLIR | J15: ACHOURA | K15: ANALYSE | L15: ADROIT | M15: ACQUERIR | N15: ALPINISME | O15: ACIDE | P15: ACONIER | Q15: ADAPTATIO | R15: ACTION | S15: AMORTI | T15: AGRANDISSE | U15: AERODROME | V15: ADDITION | W15: ACRE | X15: ADMIRATION | Y15: ACCLAMER
